Workbook

Sheet Drills
A1: 1 MONTH TO BREAK 90
A3: 3 Foot Putts (25 in a row) | B3: Drawback Drill | C3: 5-to-5 drill | D3: 75 Yards Wedge | E3: Irons - Short on Purpose | F3: Safe Side Drill
A4: Set up 5 tees, each 1 pace or 3 feet from the hole. Rotate around the tees after each putt until you make 25 putts in a row. If you miss, start over . Your score is the number of missed putts before successfully making 25 straight. A perfect score is 0. | B4: Play 9 holes on the putting green. Each is a par 2. Each hole should be 7-15 paces from the hole. Every time you miss a putt, you must move the ball 1 putter length away from the hole before attempting the next putt. Since each hole is par 2, par for 9 holes is 18. Your total score is your score relative to par. So if you 3-putt every hole, that's a 27 or +9, you'd enter a 9. | C4: Pick a spot to chip 25 yards from a hole. Hit 5 balls. You get 1 point for every ball that stops within 5 feet. Repeat for 5 holes, each 25 yards. Log your total score after 5 holes. Your score is the total number of balls out of 25 that stopped within 5 feet of the hole. | D4: Hit 10 balls on the range trying to land exactly 75 yards. Your score is the total number of balls that land within 5 yards of your 75 yard target. A perfect score is 10. | E4: Hit 10 balls with your favorite iron. The goal is to land the ball short of what you normally hit that club. Your score is the total number of balls that you hit cleanly AND land at least 10 yards short of what you normally hit that club. Think 80% swings. A perfect score is 10. | F4: Create a "Fairway" on your driving range about 40 yards wide. Pick one miss side to be the "safe" side and the other to be "OB". Scoring: Fairway = +1, Safe miss = -1, OB miss = -3 Your score is the sum of all points from you 10 shots. A perfect score is +10
A7: Week 1- Session 1 | B7: Score | C7: Weakness? Focus On?
A8: 3 Foot Putts (25 in a row) | B8: 0
A9: Drawback Drill | B9: 0
A10: 5-to-5 drill | B10: 0
A11: 75 Yards Wedge | B11: 0
A12: Irons - Short on Purpose | B12: 0
A13: Safe Side Drill | B13: 0
A15: Week 1- Session 2 | B15: Score | C15: Weakness? Focus On?
A16: 3 Foot Putts (25 in a row) | B16: 0
A17: Drawback Drill | B17: 0
A18: 5-to-5 drill | B18: 0
A19: 75 Yards Wedge | B19: 0
A20: Irons - Short on Purpose | B20: 0
A21: Safe Side Drill | B21: 0
A23: Week 2- Session 1 | B23: Score | C23: Weakness? Focus On?
A24: 3 Foot Putts (25 in a row) | B24: 0
A25: Drawback Drill | B25: 0
A26: 5-to-5 drill | B26: 0
A27: 75 Yards Wedge | B27: 0
A28: Irons - Short on Purpose | B28: 0
A29: Safe Side Drill | B29: 0
A31: Week 2- Session 2 | B31: Score | C31: Weakness? Focus On?
A32: 3 Foot Putts (25 in a row) | B32: 0
A33: Drawback Drill | B33: 0
A34: 5-to-5 drill | B34: 0
A35: 75 Yards Wedge | B35: 0
A36: Irons - Short on Purpose | B36: 0
A37: Safe Side Drill | B37: 0
A39: Week 3- Session 1 | B39: Score | C39: Weakness? Focus On?
A40: 3 Foot Putts (25 in a row) | B40: 0
A41: Drawback Drill | B41: 0
A42: 5-to-5 drill | B42: 0
A43: 75 Yards Wedge | B43: 0
A44: Irons - Short on Purpose | B44: 0
A45: Safe Side Drill | B45: 0
A47: Week 3- Session 2 | B47: Score | C47: Weakness? Focus On?
A48: 3 Foot Putts (25 in a row) | B48: 0
...

Sheet Progress Charts
A1: Session | B1: 3 Foot Putts | C1: Drawback Drill | D1: 5-to-5 Drill | E1: 75 Yards Wedge | F1: Short on Purpose | G1: Safe Side Drill | H1: Progress Charts
A2: 1 | B2: =Drills!$B8 -> 0 | C2: =Drills!$B9 -> 0 | D2: =Drills!$B10 -> 0 | E2: =Drills!$B11 -> 0 | F2: =Drills!$B12 -> 0 | G2: =Drills!$B13 -> 0
A3: 2 | B3: =Drills!$B16 -> 0 | C3: =Drills!$B17 -> 0 | D3: =Drills!$B18 -> 0 | E3: =Drills!$B19 -> 0 | F3: =Drills!$B20 -> 0 | G3: =Drills!$B21 -> 0
A4: 3 | B4: =Drills!$B24 -> 0 | C4: =Drills!$B25 -> 0 | D4: =Drills!$B26 -> 0 | E4: =Drills!$B27 -> 0 | F4: =Drills!$B28 -> 0 | G4: =Drills!$B29 -> 0
A5: 4 | B5: =Drills!$B32 -> 0 | C5: =Drills!$B33 -> 0 | D5: =Drills!$B34 -> 0 | E5: =Drills!$B35 -> 0 | F5: =Drills!$B36 -> 0 | G5: =Drills!$B37 -> 0
A6: 5 | B6: =Drills!$B40 -> 0 | C6: =Drills!$B41 -> 0 | D6: =Drills!$B42 -> 0 | E6: =Drills!$B43 -> 0 | F6: =Drills!$B44 -> 0 | G6: =Drills!$B45 -> 0
A7: 6 | B7: =Drills!$B48 -> 0 | C7: =Drills!$B49 -> 0 | D7: =Drills!$B50 -> 0 | E7: =Drills!$B51 -> 0 | F7: =Drills!$B52 -> 0 | G7: =Drills!$B53 -> 0
A8: 7 | B8: =Drills!$B56 -> 0 | C8: =Drills!$B57 -> 0 | D8: =Drills!$B58 -> 0 | E8: =Drills!$B59 -> 0 | F8: =Drills!$B60 -> 0 | G8: =Drills!$B61 -> 0
A9: 8 | B9: =Drills!$B64 -> 0 | C9: =Drills!$B65 -> 0 | D9: =Drills!$B66 -> 0 | E9: =Drills!$B67 -> 0 | F9: =Drills!$B68 -> 0 | G9: =Drills!$B69 -> 0
C10: Lower = Better | J10: Higher = Better
C11: Short Putting | J11: Chipping | P11: Partial Wedges
C31: Lag Putting | J31: Irons | P31: Driver
